Traceback (most recent call last):
  File "<frozen runpy>", line 198, in _run_module_as_main
  File "<frozen runpy>", line 88, in _run_code
  File "/data/data/com.termux/files/usr/lib/python3.12/http/server.py", line 1310, in <module>
    test(
  File "/data/data/com.termux/files/usr/lib/python3.12/http/server.py", line 1257, in test
    with ServerClass(addr, HandlerClass) as httpd:
         ^^^^^^^^^^^^^^^^^^^^^^^^^^^^^^^
  File "/data/data/com.termux/files/usr/lib/python3.12/socketserver.py", line 457, in __init__
    self.server_bind()
  File "/data/data/com.termux/files/usr/lib/python3.12/http/server.py", line 1304, in server_bind
    return super().server_bind()
           ^^^^^^^^^^^^^^^^^^^^^
  File "/data/data/com.termux/files/usr/lib/python3.12/http/server.py", line 136, in server_bind
    socketserver.TCPServer.server_bind(self)
  File "/data/data/com.termux/files/usr/lib/python3.12/socketserver.py", line 473, in server_bind
    self.socket.bind(self.server_address)
OSError: [Errno 98] Address already in use
node:events:485
      throw er; // Unhandled 'error' event
      ^

Error: listen EADDRINUSE: address already in use 0.0.0.0:8080
    at Server.setupListenHandle [as _listen2] (node:net:1937:16)
    at listenInCluster (node:net:1994:12)
    at node:net:2203:7
    at process.processTicksAndRejections (node:internal/process/task_queues:90:21)
Emitted 'error' event on Server instance at:
    at emitErrorNT (node:net:1973:8)
    at process.processTicksAndRejections (node:internal/process/task_queues:90:21) {
  code: 'EADDRINUSE',
  errno: -98,
  syscall: 'listen',
  address: '0.0.0.0',
  port: 8080
}

Node.js v23.6.0
